<?xml version="1.0"?>
<robot name="pixi_ros2_gripper_workflow_demo">
  <link name="base_link">
    <visual>
      <geometry><box size="0.1 0.1 0.05"/></geometry>
      <material name="dark_grey"><color rgba="0.2 0.2 0.2 1"/></material>
    </visual>
  </link>

  <link name="left_finger">
    <visual>
      <geometry><box size="0.08 0.02 0.04"/></geometry>
      <origin xyz="0.04 0 0" rpy="0 0 0"/>
      <material name="cyan"><color rgba="0 1 1 1"/></material>
    </visual>
  </link>

  <link name="right_finger">
    <visual>
      <geometry><box size="0.08 0.02 0.04"/></geometry>
      <origin xyz="0.04 0 0" rpy="0 0 0"/>
      <material name="cyan"><color rgba="0 1 1 1"/></material>
    </visual>
  </link>

  <joint name="left_finger_joint" type="prismatic">
    <parent link="base_link"/>
    <child link="left_finger"/>
    <origin xyz="0.05 0.01 0" rpy="0 0 0"/>
    <axis xyz="0 1 0"/>
    <limit lower="0" upper="0.04" effort="10" velocity="0.1"/>
  </joint>

  <joint name="right_finger_joint" type="prismatic">
    <parent link="base_link"/>
    <child link="right_finger"/>
    <origin xyz="0.05 -0.01 0" rpy="0 0 0"/>
    <axis xyz="0 -1 0"/>
    <limit lower="0" upper="0.04" effort="10" velocity="0.1"/>
  </joint>
</robot>
